2018-01-16 19:26:27,980 ERROR: Exception on /edit_profile/saven [GET] [in c:\program files\python37\lib\site-packages\flask\app.py:1560]
Traceback (most recent call last):
  File "c:\program files\python37\lib\site-packages\flask\app.py", line 1982, in wsgi_app
    response = self.full_dispatch_request()
  File "c:\program files\python37\lib\site-packages\flask\app.py", line 1614, in full_dispatch_request
    rv = self.handle_user_exception(e)
  File "c:\program files\python37\lib\site-packages\flask\app.py", line 1517, in handle_user_exception
    reraise(exc_type, exc_value, tb)
  File "c:\program files\python37\lib\site-packages\flask\_compat.py", line 33, in reraise
    raise value
  File "c:\program files\python37\lib\site-packages\flask\app.py", line 1612, in full_dispatch_request
    rv = self.dispatch_request()
  File "c:\program files\python37\lib\site-packages\flask\app.py", line 1598, in dispatch_request
    return self.view_functions[rule.endpoint](**req.view_args)
  File "c:\program files\python37\lib\site-packages\flask_login\utils.py", line 261, in decorated_view
    return func(*args, **kwargs)
  File "C:\Users\saven\Documents\calc\package\routes.py", line 81, in edit_profile
    form = EditProfileForm(username=username)
  File "c:\program files\python37\lib\site-packages\wtforms\form.py", line 212, in __call__
    return type.__call__(cls, *args, **kwargs)
TypeError: __init__() missing 1 required positional argument: 'original_username'
2018-01-16 19:29:07,639 INFO: Calculator startup [in C:\Users\saven\Documents\calc\package\__init__.py:43]
2018-01-16 19:34:07,663 INFO: Calculator startup [in C:\Users\saven\Documents\calc\package\__init__.py:43]
2018-01-16 19:39:45,459 ERROR: Exception on /unfollow/sebastian.borer [GET] [in c:\program files\python37\lib\site-packages\flask\app.py:1560]
Traceback (most recent call last):
  File "c:\program files\python37\lib\site-packages\flask\app.py", line 1982, in wsgi_app
    response = self.full_dispatch_request()
  File "c:\program files\python37\lib\site-packages\flask\app.py", line 1614, in full_dispatch_request
    rv = self.handle_user_exception(e)
  File "c:\program files\python37\lib\site-packages\flask\app.py", line 1517, in handle_user_exception
    reraise(exc_type, exc_value, tb)
  File "c:\program files\python37\lib\site-packages\flask\_compat.py", line 33, in reraise
    raise value
  File "c:\program files\python37\lib\site-packages\flask\app.py", line 1612, in full_dispatch_request
    rv = self.dispatch_request()
  File "c:\program files\python37\lib\site-packages\flask\app.py", line 1598, in dispatch_request
    return self.view_functions[rule.endpoint](**req.view_args)
  File "c:\program files\python37\lib\site-packages\flask_login\utils.py", line 261, in decorated_view
    return func(*args, **kwargs)
  File "C:\Users\saven\Documents\calc\package\routes.py", line 124, in unfollow
    sb.session.commit()
NameError: name 'sb' is not defined
2018-01-16 19:40:45,964 INFO: Calculator startup [in C:\Users\saven\Documents\calc\package\__init__.py:43]
2018-01-16 19:54:02,625 INFO: Calculator startup [in C:\Users\saven\Documents\calc\package\__init__.py:43]
2018-01-16 19:59:17,288 INFO: Calculator startup [in C:\Users\saven\Documents\calc\package\__init__.py:43]
2018-01-16 19:59:54,614 ERROR: Exception on /login [POST] [in c:\program files\python37\lib\site-packages\flask\app.py:1560]
Traceback (most recent call last):
  File "c:\program files\python37\lib\site-packages\flask\app.py", line 1982, in wsgi_app
    response = self.full_dispatch_request()
  File "c:\program files\python37\lib\site-packages\flask\app.py", line 1614, in full_dispatch_request
    rv = self.handle_user_exception(e)
  File "c:\program files\python37\lib\site-packages\flask\app.py", line 1517, in handle_user_exception
    reraise(exc_type, exc_value, tb)
  File "c:\program files\python37\lib\site-packages\flask\_compat.py", line 33, in reraise
    raise value
  File "c:\program files\python37\lib\site-packages\flask\app.py", line 1612, in full_dispatch_request
    rv = self.dispatch_request()
  File "c:\program files\python37\lib\site-packages\flask\app.py", line 1598, in dispatch_request
    return self.view_functions[rule.endpoint](**req.view_args)
  File "C:\Users\saven\Documents\calc\package\routes.py", line 40, in login
    for k, v in request.args:
ValueError: too many values to unpack (expected 2)
2018-01-16 20:00:55,170 INFO: Calculator startup [in C:\Users\saven\Documents\calc\package\__init__.py:43]
2018-01-16 20:01:43,076 INFO: Calculator startup [in C:\Users\saven\Documents\calc\package\__init__.py:43]
2018-01-16 20:21:14,684 INFO: Calculator startup [in C:\Users\saven\Documents\calc\package\__init__.py:43]
2018-01-16 20:41:11,626 INFO: Calculator startup [in C:\Users\saven\Documents\calc\package\__init__.py:43]
2018-01-16 20:59:57,016 INFO: Calculator startup [in C:\Users\saven\Documents\calc\package\__init__.py:43]
2018-01-16 21:02:29,043 INFO: Calculator startup [in C:\Users\saven\Documents\calc\package\__init__.py:43]
2018-01-16 21:03:51,104 INFO: Calculator startup [in C:\Users\saven\Documents\calc\package\__init__.py:43]
2018-01-16 21:23:38,433 INFO: Calculator startup [in C:\Users\saven\Documents\calc\package\__init__.py:43]
2018-01-17 17:34:29,340 INFO: Calculator startup [in C:\calc\package\__init__.py:43]
2018-01-17 17:40:03,193 INFO: Calculator startup [in C:\calc\package\__init__.py:46]
2018-01-17 17:56:56,205 INFO: Calculator startup [in C:\calc\package\__init__.py:46]
2018-01-17 17:57:00,922 ERROR: Exception on /login [GET] [in c:\program files\python37\lib\site-packages\flask\app.py:1560]
Traceback (most recent call last):
  File "c:\program files\python37\lib\site-packages\flask\app.py", line 1982, in wsgi_app
    response = self.full_dispatch_request()
  File "c:\program files\python37\lib\site-packages\flask\app.py", line 1614, in full_dispatch_request
    rv = self.handle_user_exception(e)
  File "c:\program files\python37\lib\site-packages\flask\app.py", line 1517, in handle_user_exception
    reraise(exc_type, exc_value, tb)
  File "c:\program files\python37\lib\site-packages\flask\_compat.py", line 33, in reraise
    raise value
  File "c:\program files\python37\lib\site-packages\flask\app.py", line 1612, in full_dispatch_request
    rv = self.dispatch_request()
  File "c:\program files\python37\lib\site-packages\flask\app.py", line 1598, in dispatch_request
    return self.view_functions[rule.endpoint](**req.view_args)
  File "C:\calc\package\routes.py", line 52, in login
    return render_template('login.html', title='Sign In', form=form)
  File "c:\program files\python37\lib\site-packages\flask\templating.py", line 134, in render_template
    context, ctx.app)
  File "c:\program files\python37\lib\site-packages\flask\templating.py", line 116, in _render
    rv = template.render(context)
  File "c:\program files\python37\lib\site-packages\jinja2\asyncsupport.py", line 76, in render
    return original_render(self, *args, **kwargs)
  File "c:\program files\python37\lib\site-packages\jinja2\environment.py", line 1008, in render
    return self.environment.handle_exception(exc_info, True)
  File "c:\program files\python37\lib\site-packages\jinja2\environment.py", line 780, in handle_exception
    reraise(exc_type, exc_value, tb)
  File "c:\program files\python37\lib\site-packages\jinja2\_compat.py", line 37, in reraise
    raise value.with_traceback(tb)
  File "C:\calc\package\templates\login.html", line 1, in top-level template code
    {% extends "base.html" %}
  File "C:\calc\package\templates\base.html", line 34, in top-level template code
    {% block content %}{% endblock %}
  File "C:\calc\package\templates\login.html", line 26, in block "content"
    <a href="{{ url_for('reset_password_request') }}">Click to Reset It</a>
  File "c:\program files\python37\lib\site-packages\flask\helpers.py", line 333, in url_for
    return appctx.app.handle_url_build_error(error, endpoint, values)
  File "c:\program files\python37\lib\site-packages\flask\app.py", line 1805, in handle_url_build_error
    reraise(exc_type, exc_value, tb)
  File "c:\program files\python37\lib\site-packages\flask\_compat.py", line 33, in reraise
    raise value
  File "c:\program files\python37\lib\site-packages\flask\helpers.py", line 323, in url_for
    force_external=external)
  File "c:\program files\python37\lib\site-packages\werkzeug\routing.py", line 1776, in build
    raise BuildError(endpoint, values, method, self)
werkzeug.routing.BuildError: Could not build url for endpoint 'reset_password_request'. Did you mean 'edit_profile' instead?
2018-01-17 20:44:10,081 INFO: Calculator startup [in C:\calc\package\__init__.py:46]
