2018-01-18 00:44:17,413 ERROR: Exception on /index [GET] [in c:\program files\python37\lib\site-packages\flask\app.py:1560]
Traceback (most recent call last):
  File "c:\program files\python37\lib\site-packages\flask\app.py", line 1982, in wsgi_app
    response = self.full_dispatch_request()
  File "c:\program files\python37\lib\site-packages\flask\app.py", line 1614, in full_dispatch_request
    rv = self.handle_user_exception(e)
  File "c:\program files\python37\lib\site-packages\flask\app.py", line 1517, in handle_user_exception
    reraise(exc_type, exc_value, tb)
  File "c:\program files\python37\lib\site-packages\flask\_compat.py", line 33, in reraise
    raise value
  File "c:\program files\python37\lib\site-packages\flask\app.py", line 1612, in full_dispatch_request
    rv = self.dispatch_request()
  File "c:\program files\python37\lib\site-packages\flask\app.py", line 1598, in dispatch_request
    return self.view_functions[rule.endpoint](**req.view_args)
  File "c:\program files\python37\lib\site-packages\flask_login\utils.py", line 261, in decorated_view
    return func(*args, **kwargs)
  File "C:\calc\package\routes.py", line 34, in index
    next_url=next_url, prev_url=prev_url)
  File "c:\program files\python37\lib\site-packages\flask\templating.py", line 134, in render_template
    context, ctx.app)
  File "c:\program files\python37\lib\site-packages\flask\templating.py", line 116, in _render
    rv = template.render(context)
  File "c:\program files\python37\lib\site-packages\jinja2\asyncsupport.py", line 76, in render
    return original_render(self, *args, **kwargs)
  File "c:\program files\python37\lib\site-packages\jinja2\environment.py", line 1008, in render
    return self.environment.handle_exception(exc_info, True)
  File "c:\program files\python37\lib\site-packages\jinja2\environment.py", line 780, in handle_exception
    reraise(exc_type, exc_value, tb)
  File "c:\program files\python37\lib\site-packages\jinja2\_compat.py", line 37, in reraise
    raise value.with_traceback(tb)
  File "C:\calc\package\templates\base.html", line 51, in template
    {% endblock %}
  File "c:\program files\python37\lib\site-packages\jinja2\environment.py", line 1005, in render
    return concat(self.root_render_func(self.new_context(vars)))
  File "C:\calc\package\templates\index.html", line 1, in top-level template code
    {% extends "base.html" %}
  File "c:\program files\python37\lib\site-packages\jinja2\environment.py", line 780, in handle_exception
    reraise(exc_type, exc_value, tb)
  File "c:\program files\python37\lib\site-packages\jinja2\_compat.py", line 37, in reraise
    raise value.with_traceback(tb)
  File "C:\calc\package\templates\base.html", line 51, in template
    {% endblock %}
  File "c:\program files\python37\lib\site-packages\jinja2\environment.py", line 497, in _parse
    return Parser(self, source, name, encode_filename(filename)).parse()
  File "c:\program files\python37\lib\site-packages\jinja2\parser.py", line 901, in parse
    result = nodes.Template(self.subparse(), lineno=1)
  File "c:\program files\python37\lib\site-packages\jinja2\parser.py", line 883, in subparse
    rv = self.parse_statement()
  File "c:\program files\python37\lib\site-packages\jinja2\parser.py", line 130, in parse_statement
    return getattr(self, 'parse_' + self.stream.current.value)()
  File "c:\program files\python37\lib\site-packages\jinja2\parser.py", line 268, in parse_block
    node.body = self.parse_statements(('name:endblock',), drop_needle=True)
  File "c:\program files\python37\lib\site-packages\jinja2\parser.py", line 170, in parse_statements
    self.fail_eof(end_tokens)
  File "c:\program files\python37\lib\site-packages\jinja2\parser.py", line 104, in fail_eof
    return self._fail_ut_eof(None, stack, lineno)
  File "c:\program files\python37\lib\site-packages\jinja2\parser.py", line 90, in _fail_ut_eof
    self.fail(' '.join(message), lineno)
  File "c:\program files\python37\lib\site-packages\jinja2\parser.py", line 59, in fail
    raise exc(msg, lineno, self.name, self.filename)
jinja2.exceptions.TemplateSyntaxError: Unexpected end of template. Jinja was looking for the following tags: 'endblock'. The innermost block that needs to be closed is 'block'.
2018-01-18 00:46:21,431 INFO: Calculator startup [in C:\calc\package\__init__.py:47]
2018-01-18 00:47:06,949 ERROR: Exception on /login [GET] [in c:\program files\python37\lib\site-packages\flask\app.py:1560]
Traceback (most recent call last):
  File "c:\program files\python37\lib\site-packages\flask\app.py", line 1982, in wsgi_app
    response = self.full_dispatch_request()
  File "c:\program files\python37\lib\site-packages\flask\app.py", line 1614, in full_dispatch_request
    rv = self.handle_user_exception(e)
  File "c:\program files\python37\lib\site-packages\flask\app.py", line 1517, in handle_user_exception
    reraise(exc_type, exc_value, tb)
  File "c:\program files\python37\lib\site-packages\flask\_compat.py", line 33, in reraise
    raise value
  File "c:\program files\python37\lib\site-packages\flask\app.py", line 1612, in full_dispatch_request
    rv = self.dispatch_request()
  File "c:\program files\python37\lib\site-packages\flask\app.py", line 1598, in dispatch_request
    return self.view_functions[rule.endpoint](**req.view_args)
  File "C:\calc\package\routes.py", line 54, in login
    return render_template('login.html', title='Sign In', form=form)
  File "c:\program files\python37\lib\site-packages\flask\templating.py", line 134, in render_template
    context, ctx.app)
  File "c:\program files\python37\lib\site-packages\flask\templating.py", line 116, in _render
    rv = template.render(context)
  File "c:\program files\python37\lib\site-packages\jinja2\asyncsupport.py", line 76, in render
    return original_render(self, *args, **kwargs)
  File "c:\program files\python37\lib\site-packages\jinja2\environment.py", line 1008, in render
    return self.environment.handle_exception(exc_info, True)
  File "c:\program files\python37\lib\site-packages\jinja2\environment.py", line 780, in handle_exception
    reraise(exc_type, exc_value, tb)
  File "c:\program files\python37\lib\site-packages\jinja2\_compat.py", line 37, in reraise
    raise value.with_traceback(tb)
  File "C:\calc\package\templates\login.html", line 2, in top-level template code
    {% import 'bootstrap/wtf.html' as wtf %}
  File "C:\calc\package\templates\base.html", line 1, in top-level template code
    {% extends 'bootstrap/base.html' %}
  File "c:\program files\python37\lib\site-packages\flask_bootstrap\templates\bootstrap\base.html", line 1, in top-level template code
    {% block doc -%}
  File "c:\program files\python37\lib\site-packages\flask_bootstrap\templates\bootstrap\base.html", line 4, in block "doc"
    {%- block html %}
  File "c:\program files\python37\lib\site-packages\flask_bootstrap\templates\bootstrap\base.html", line 20, in block "html"
    {% block body -%}
  File "c:\program files\python37\lib\site-packages\flask_bootstrap\templates\bootstrap\base.html", line 21, in block "body"
    {% block navbar %}
  File "C:\calc\package\templates\base.html", line 31, in block "navbar"
    {% if current_user.is_admin() %}
jinja2.exceptions.UndefinedError: 'flask_login.mixins.AnonymousUserMixin object' has no attribute 'is_admin'
2018-01-18 00:48:53,357 INFO: Calculator startup [in C:\calc\package\__init__.py:47]
2018-01-18 00:49:18,341 ERROR: Exception on /register [POST] [in c:\program files\python37\lib\site-packages\flask\app.py:1560]
Traceback (most recent call last):
  File "c:\program files\python37\lib\site-packages\flask\app.py", line 1982, in wsgi_app
    response = self.full_dispatch_request()
  File "c:\program files\python37\lib\site-packages\flask\app.py", line 1614, in full_dispatch_request
    rv = self.handle_user_exception(e)
  File "c:\program files\python37\lib\site-packages\flask\app.py", line 1517, in handle_user_exception
    reraise(exc_type, exc_value, tb)
  File "c:\program files\python37\lib\site-packages\flask\_compat.py", line 33, in reraise
    raise value
  File "c:\program files\python37\lib\site-packages\flask\app.py", line 1612, in full_dispatch_request
    rv = self.dispatch_request()
  File "c:\program files\python37\lib\site-packages\flask\app.py", line 1598, in dispatch_request
    return self.view_functions[rule.endpoint](**req.view_args)
  File "C:\calc\package\routes.py", line 66, in register
    if form.validate_on_submit():
  File "c:\program files\python37\lib\site-packages\flask_wtf\form.py", line 101, in validate_on_submit
    return self.is_submitted() and self.validate()
  File "c:\program files\python37\lib\site-packages\wtforms\form.py", line 310, in validate
    return super(Form, self).validate(extra)
  File "c:\program files\python37\lib\site-packages\wtforms\form.py", line 152, in validate
    if not field.validate(self, extra):
  File "c:\program files\python37\lib\site-packages\wtforms\fields\core.py", line 204, in validate
    stop_validation = self._run_validation_chain(form, chain)
  File "c:\program files\python37\lib\site-packages\wtforms\fields\core.py", line 224, in _run_validation_chain
    validator(form, self)
  File "C:\calc\package\forms.py", line 21, in validate_username
    user = User.query.filter_by(username=username.data).first()
NameError: name 'User' is not defined
2018-01-18 00:51:17,452 INFO: Calculator startup [in C:\calc\package\__init__.py:47]
2018-01-18 00:53:47,170 INFO: Calculator startup [in C:\calc\package\__init__.py:47]
2018-01-18 00:55:02,862 INFO: Calculator startup [in C:\calc\package\__init__.py:47]
2018-01-18 00:56:56,668 INFO: Calculator startup [in C:\calc\package\__init__.py:47]
2018-01-18 00:58:00,840 INFO: Calculator startup [in C:\calc\package\__init__.py:47]
2018-01-18 01:00:21,561 INFO: Calculator startup [in C:\calc\package\__init__.py:47]
2018-01-18 01:01:16,854 INFO: Calculator startup [in C:\calc\package\__init__.py:47]
2018-01-18 01:02:05,549 INFO: Calculator startup [in C:\calc\package\__init__.py:47]
