2018-01-21 00:12:44,037 ERROR: Exception on /auth/login [GET] [in c:\program files (x86)\python36-32\lib\site-packages\flask\app.py:1560]
Traceback (most recent call last):
  File "c:\program files (x86)\python36-32\lib\site-packages\flask\app.py", line 1982, in wsgi_app
    response = self.full_dispatch_request()
  File "c:\program files (x86)\python36-32\lib\site-packages\flask\app.py", line 1614, in full_dispatch_request
    rv = self.handle_user_exception(e)
  File "c:\program files (x86)\python36-32\lib\site-packages\flask\app.py", line 1517, in handle_user_exception
    reraise(exc_type, exc_value, tb)
  File "c:\program files (x86)\python36-32\lib\site-packages\flask\_compat.py", line 33, in reraise
    raise value
  File "c:\program files (x86)\python36-32\lib\site-packages\flask\app.py", line 1612, in full_dispatch_request
    rv = self.dispatch_request()
  File "c:\program files (x86)\python36-32\lib\site-packages\flask\app.py", line 1598, in dispatch_request
    return self.view_functions[rule.endpoint](**req.view_args)
  File "C:\calc\package\blueprints\auth\routes.py", line 31, in login
    return render_template('login.html', title=_('Sign In'), form=form)
  File "c:\program files (x86)\python36-32\lib\site-packages\flask\templating.py", line 134, in render_template
    context, ctx.app)
  File "c:\program files (x86)\python36-32\lib\site-packages\flask\templating.py", line 116, in _render
    rv = template.render(context)
  File "c:\program files (x86)\python36-32\lib\site-packages\jinja2\asyncsupport.py", line 76, in render
    return original_render(self, *args, **kwargs)
  File "c:\program files (x86)\python36-32\lib\site-packages\jinja2\environment.py", line 1008, in render
    return self.environment.handle_exception(exc_info, True)
  File "c:\program files (x86)\python36-32\lib\site-packages\jinja2\environment.py", line 780, in handle_exception
    reraise(exc_type, exc_value, tb)
  File "c:\program files (x86)\python36-32\lib\site-packages\jinja2\_compat.py", line 37, in reraise
    raise value.with_traceback(tb)
  File "C:\calc\package\blueprints\auth\templates\login.html", line 1, in top-level template code
    {% extends "base.html" %}
  File "C:\calc\package\blueprints\main\templates\base.html", line 2, in top-level template code
    {% import 'bootstrap/wtf.html' as wtf %}
  File "c:\program files (x86)\python36-32\lib\site-packages\flask_bootstrap\templates\bootstrap\base.html", line 1, in top-level template code
    {% block doc -%}
  File "c:\program files (x86)\python36-32\lib\site-packages\flask_bootstrap\templates\bootstrap\base.html", line 4, in block "doc"
    {%- block html %}
  File "c:\program files (x86)\python36-32\lib\site-packages\flask_bootstrap\templates\bootstrap\base.html", line 20, in block "html"
    {% block body -%}
  File "c:\program files (x86)\python36-32\lib\site-packages\flask_bootstrap\templates\bootstrap\base.html", line 21, in block "body"
    {% block navbar %}
  File "C:\calc\package\blueprints\main\templates\base.html", line 23, in block "navbar"
    <li><a href="{{ url_for('explore') }}">{{ _('Explore') }}</a></li>
  File "c:\program files (x86)\python36-32\lib\site-packages\flask\helpers.py", line 333, in url_for
    return appctx.app.handle_url_build_error(error, endpoint, values)
  File "c:\program files (x86)\python36-32\lib\site-packages\flask\app.py", line 1805, in handle_url_build_error
    reraise(exc_type, exc_value, tb)
  File "c:\program files (x86)\python36-32\lib\site-packages\flask\_compat.py", line 33, in reraise
    raise value
  File "c:\program files (x86)\python36-32\lib\site-packages\flask\helpers.py", line 323, in url_for
    force_external=external)
  File "c:\program files (x86)\python36-32\lib\site-packages\werkzeug\routing.py", line 1776, in build
    raise BuildError(endpoint, values, method, self)
werkzeug.routing.BuildError: Could not build url for endpoint 'explore'. Did you mean 'main.explore' instead?
2018-01-21 00:13:22,395 INFO: Mavki startup [in C:\calc\package\core\__init__.py:74]
2018-01-21 00:13:23,502 ERROR: Exception on /auth/login [GET] [in c:\program files (x86)\python36-32\lib\site-packages\flask\app.py:1560]
Traceback (most recent call last):
  File "c:\program files (x86)\python36-32\lib\site-packages\flask\app.py", line 1982, in wsgi_app
    response = self.full_dispatch_request()
  File "c:\program files (x86)\python36-32\lib\site-packages\flask\app.py", line 1614, in full_dispatch_request
    rv = self.handle_user_exception(e)
  File "c:\program files (x86)\python36-32\lib\site-packages\flask\app.py", line 1517, in handle_user_exception
    reraise(exc_type, exc_value, tb)
  File "c:\program files (x86)\python36-32\lib\site-packages\flask\_compat.py", line 33, in reraise
    raise value
  File "c:\program files (x86)\python36-32\lib\site-packages\flask\app.py", line 1612, in full_dispatch_request
    rv = self.dispatch_request()
  File "c:\program files (x86)\python36-32\lib\site-packages\flask\app.py", line 1598, in dispatch_request
    return self.view_functions[rule.endpoint](**req.view_args)
  File "C:\calc\package\blueprints\auth\routes.py", line 31, in login
    return render_template('login.html', title=_('Sign In'), form=form)
  File "c:\program files (x86)\python36-32\lib\site-packages\flask\templating.py", line 134, in render_template
    context, ctx.app)
  File "c:\program files (x86)\python36-32\lib\site-packages\flask\templating.py", line 116, in _render
    rv = template.render(context)
  File "c:\program files (x86)\python36-32\lib\site-packages\jinja2\asyncsupport.py", line 76, in render
    return original_render(self, *args, **kwargs)
  File "c:\program files (x86)\python36-32\lib\site-packages\jinja2\environment.py", line 1008, in render
    return self.environment.handle_exception(exc_info, True)
  File "c:\program files (x86)\python36-32\lib\site-packages\jinja2\environment.py", line 780, in handle_exception
    reraise(exc_type, exc_value, tb)
  File "c:\program files (x86)\python36-32\lib\site-packages\jinja2\_compat.py", line 37, in reraise
    raise value.with_traceback(tb)
  File "C:\calc\package\blueprints\auth\templates\login.html", line 1, in top-level template code
    {% extends "base.html" %}
  File "C:\calc\package\blueprints\main\templates\base.html", line 2, in top-level template code
    {% import 'bootstrap/wtf.html' as wtf %}
  File "c:\program files (x86)\python36-32\lib\site-packages\flask_bootstrap\templates\bootstrap\base.html", line 1, in top-level template code
    {% block doc -%}
  File "c:\program files (x86)\python36-32\lib\site-packages\flask_bootstrap\templates\bootstrap\base.html", line 4, in block "doc"
    {%- block html %}
  File "c:\program files (x86)\python36-32\lib\site-packages\flask_bootstrap\templates\bootstrap\base.html", line 20, in block "html"
    {% block body -%}
  File "c:\program files (x86)\python36-32\lib\site-packages\flask_bootstrap\templates\bootstrap\base.html", line 21, in block "body"
    {% block navbar %}
  File "C:\calc\package\blueprints\main\templates\base.html", line 27, in block "navbar"
    <li><a href="{{ url_for('login') }}">{{ _('Login') }}</a></li>
  File "c:\program files (x86)\python36-32\lib\site-packages\flask\helpers.py", line 333, in url_for
    return appctx.app.handle_url_build_error(error, endpoint, values)
  File "c:\program files (x86)\python36-32\lib\site-packages\flask\app.py", line 1805, in handle_url_build_error
    reraise(exc_type, exc_value, tb)
  File "c:\program files (x86)\python36-32\lib\site-packages\flask\_compat.py", line 33, in reraise
    raise value
  File "c:\program files (x86)\python36-32\lib\site-packages\flask\helpers.py", line 323, in url_for
    force_external=external)
  File "c:\program files (x86)\python36-32\lib\site-packages\werkzeug\routing.py", line 1776, in build
    raise BuildError(endpoint, values, method, self)
werkzeug.routing.BuildError: Could not build url for endpoint 'login'. Did you mean 'auth.login' instead?
2018-01-21 00:14:13,798 INFO: Mavki startup [in C:\calc\package\core\__init__.py:74]
