2018-01-29 06:51:03,855 INFO: Mavki startup [in /home/mavki/mavki/package/core/__init__.py:77]
2018-01-29 06:51:12,236 INFO: Mavki startup [in /home/mavki/mavki/package/core/__init__.py:77]
2018-01-29 06:51:24,501 INFO: Mavki startup [in /home/mavki/mavki/package/core/__init__.py:77]
2018-01-29 06:53:36,772 INFO: Mavki startup [in /home/mavki/mavki/package/core/__init__.py:77]
2018-01-29 11:41:52,268 INFO: Mavki startup [in /home/mavki/mavki/package/core/__init__.py:77]
2018-01-29 11:41:52,345 INFO: Mavki startup [in /home/mavki/mavki/package/core/__init__.py:77]
2018-01-29 11:41:54,651 ERROR: Exception on /user/nitroc99 [GET] [in /usr/local/lib/python3.5/dist-packages/flask/app.py:1560]
Traceback (most recent call last):
  File "/usr/local/lib/python3.5/dist-packages/sqlalchemy/engine/base.py", line 1193, in _execute_context
    context)
  File "/usr/local/lib/python3.5/dist-packages/sqlalchemy/engine/default.py", line 507, in do_execute
    cursor.execute(statement, parameters)
sqlite3.OperationalError: attempt to write a readonly database

The above exception was the direct cause of the following exception:

Traceback (most recent call last):
  File "/usr/local/lib/python3.5/dist-packages/flask/app.py", line 1982, in wsgi_app
    response = self.full_dispatch_request()
  File "/usr/local/lib/python3.5/dist-packages/flask/app.py", line 1614, in full_dispatch_request
    rv = self.handle_user_exception(e)
  File "/usr/local/lib/python3.5/dist-packages/flask/app.py", line 1517, in handle_user_exception
    reraise(exc_type, exc_value, tb)
  File "/usr/local/lib/python3.5/dist-packages/flask/_compat.py", line 33, in reraise
    raise value
  File "/usr/local/lib/python3.5/dist-packages/flask/app.py", line 1610, in full_dispatch_request
    rv = self.preprocess_request()
  File "/usr/local/lib/python3.5/dist-packages/flask/app.py", line 1831, in preprocess_request
    rv = func()
  File "/home/mavki/mavki/package/blueprints/main/routes.py", line 16, in before_request
    db.session.commit()
  File "/usr/local/lib/python3.5/dist-packages/sqlalchemy/orm/scoping.py", line 153, in do
    return getattr(self.registry(), name)(*args, **kwargs)
  File "/usr/local/lib/python3.5/dist-packages/sqlalchemy/orm/session.py", line 943, in commit
    self.transaction.commit()
  File "/usr/local/lib/python3.5/dist-packages/sqlalchemy/orm/session.py", line 467, in commit
    self._prepare_impl()
  File "/usr/local/lib/python3.5/dist-packages/sqlalchemy/orm/session.py", line 447, in _prepare_impl
    self.session.flush()
  File "/usr/local/lib/python3.5/dist-packages/sqlalchemy/orm/session.py", line 2243, in flush
    self._flush(objects)
  File "/usr/local/lib/python3.5/dist-packages/sqlalchemy/orm/session.py", line 2369, in _flush
    transaction.rollback(_capture_exception=True)
  File "/usr/local/lib/python3.5/dist-packages/sqlalchemy/util/langhelpers.py", line 66, in __exit__
    compat.reraise(exc_type, exc_value, exc_tb)
  File "/usr/local/lib/python3.5/dist-packages/sqlalchemy/util/compat.py", line 187, in reraise
    raise value
  File "/usr/local/lib/python3.5/dist-packages/sqlalchemy/orm/session.py", line 2333, in _flush
    flush_context.execute()
  File "/usr/local/lib/python3.5/dist-packages/sqlalchemy/orm/unitofwork.py", line 391, in execute
    rec.execute(self)
  File "/usr/local/lib/python3.5/dist-packages/sqlalchemy/orm/unitofwork.py", line 556, in execute
    uow
  File "/usr/local/lib/python3.5/dist-packages/sqlalchemy/orm/persistence.py", line 177, in save_obj
    mapper, table, update)
  File "/usr/local/lib/python3.5/dist-packages/sqlalchemy/orm/persistence.py", line 768, in _emit_update_statements
    execute(statement, multiparams)
  File "/usr/local/lib/python3.5/dist-packages/sqlalchemy/engine/base.py", line 948, in execute
    return meth(self, multiparams, params)
  File "/usr/local/lib/python3.5/dist-packages/sqlalchemy/sql/elements.py", line 269, in _execute_on_connection
    return connection._execute_clauseelement(self, multiparams, params)
  File "/usr/local/lib/python3.5/dist-packages/sqlalchemy/engine/base.py", line 1060, in _execute_clauseelement
    compiled_sql, distilled_params
  File "/usr/local/lib/python3.5/dist-packages/sqlalchemy/engine/base.py", line 1200, in _execute_context
    context)
  File "/usr/local/lib/python3.5/dist-packages/sqlalchemy/engine/base.py", line 1413, in _handle_dbapi_exception
    exc_info
  File "/usr/local/lib/python3.5/dist-packages/sqlalchemy/util/compat.py", line 203, in raise_from_cause
    reraise(type(exception), exception, tb=exc_tb, cause=cause)
  File "/usr/local/lib/python3.5/dist-packages/sqlalchemy/util/compat.py", line 186, in reraise
    raise value.with_traceback(tb)
  File "/usr/local/lib/python3.5/dist-packages/sqlalchemy/engine/base.py", line 1193, in _execute_context
    context)
  File "/usr/local/lib/python3.5/dist-packages/sqlalchemy/engine/default.py", line 507, in do_execute
    cursor.execute(statement, parameters)
sqlalchemy.exc.OperationalError: (sqlite3.OperationalError) attempt to write a readonly database [SQL: 'UPDATE user SET last_seen=? WHERE user.id = ?'] [parameters: ('2018-01-29 10:41:54.649642', 1)] (Background on this error at: http://sqlalche.me/e/e3q8)
2018-01-29 12:53:45,265 INFO: Mavki startup [in /home/mavki/mavki/package/core/__init__.py:77]
2018-01-29 12:53:45,313 INFO: Mavki startup [in /home/mavki/mavki/package/core/__init__.py:77]
